<?xml version="1.0"?>
	<robot name="lab">
		<link name="base_link">
			<visual>
				<origin rpy="1.57075 0 -1.57075" xyz="0.095 0.1664 0.05"/>
			</visual>
		</link>

		<link name="motor_left">
			<visual>
				<origin rpy="-1.57075 0 0" xyz="-0.02 -0.061 0"/>
			</visual>
		</link>

		<joint name="base_link_to_motor_left" type="fixed">
			<parent link="base_link"/>
			<child link="motor_left"/>
			<origin xyz="0 0.07 0.059"/>
		</joint>
		
		<link name="motor_right">
			<visual>
				<origin rpy="-1.57075 0 3.14159" xyz="0.02 0.061 0"/>
			</visual>
		</link>

		<joint name="base_link_to_motor_right" type="fixed">
			<parent link="base_link"/>
			<child link="motor_right"/>
			<origin xyz="0 -0.07 0.059"/>
		</joint>
		
		<link name="wheel_left">
			<visual>
				<origin rpy="1.57075 0 0" xyz="-0.04 0.02 -0.04"/>
			</visual>
		</link>	
			
		<joint name="motor_left_to_wheel_left" type="continuous">
			<parent link="motor_left"/>
			<child link="wheel_left"/>
			<origin xyz="0 0.023 -0.019"/>
			<axis xyz="0 1 0"/>
		</joint>
		
		<link name="wheel_right">
			<visual>
				<origin rpy="1.57075 0 0" xyz="-0.04 0.02 -0.04"/>
			</visual>
		</link>	
			
		<joint name="motor_right_to_wheel_right" type="continuous">
			<parent link="motor_right"/>
			<child link="wheel_right"/>
			<origin xyz="0 -0.023 -0.019"/>
			<axis xyz="0 1 0"/>
		</joint>
		
		<link name="scan">
			<visual>
				<origin rpy="0 0 1.57075" xyz="0.03 -0.14 0.04"/>
			</visual>
		</link>

		<joint name="base_link_to_scan" type="continuous">
			<parent link="base_link"/>
			<child link="scan"/>
			<origin xyz="-0.0065 0 0.139"/>
			<axis xyz="0 1 0"/>
		</joint>	
		
	</robot>